Traceback (most recent call last):
  File "/home/bogdan/Рабочий стол/PythonNosinovskiy/mod5/task4/tests/test_task4.py", line 10, in test_stdout_file
    raise Exception('Hello stderr.txt')
Exception: Hello stderr.txt
